<?xml version="1.0" encoding="utf-8"?>
<!-- This URDF was automatically created by SolidWorks to URDF Exporter! Originally created by Stephen Brawner (brawner@gmail.com) 
     Commit Version: 1.6.0-4-g7f85cfe  Build Version: 1.6.7995.38578
     For more information, please see http://wiki.ros.org/sw_urdf_exporter -->



<robot  name="waiter_robot_1" xmlns:xacro="http://ros.org/wiki/xacro">
  <xacro:include filename="$(find waiter_robot_1)/urdf/waiter_common_properties.xacro"/>
  <xacro:include filename="$(find waiter_robot_1)/urdf/waiter_robot_1.gazebo.xacro"/>



  <link name="base_footprint"/>

  <joint name="base_joint" type="fixed">
    <parent link="base_footprint"/>
    <child link="base_link"/>
    <origin xyz="0.0 0.0 0.0" rpy="0 0 0"/>
  </joint>

  <link name="base_link">
    <inertial>
      <origin
        xyz="0.014375 0.00017948 0.041436"
        rpy="0 0 0" />
      <mass
        value="5.3045" />
      <inertia
        ixx="0.02574"
        ixy="-4.8944E-08"
        ixz="-1.5815E-08"
        iyy="0.051134"
        iyz="-5.7053E-08"
        izz="0.070862" />
    </inertial>
    <visual>
      <origin
        xyz="0 0 0"
        rpy="0 0 0" />
      <geometry>
        <mesh
          filename="package://waiter_robot_1/meshes/base_link.STL" />
      </geometry>
      <material
        name="">
        <color
          rgba="1 1 1 1" />
      </material>
    </visual>
    <collision>
      <origin
        xyz="0 0 0"
        rpy="0 0 0" />
      <geometry>
        <mesh
          filename="package://waiter_robot_1/meshes/base_link.STL" />
      </geometry>
    </collision>
  </link>

  <joint name="wheel_left_joint" type="continuous">
    <origin
      xyz="-0.075 0.1942 -0.0125"
      rpy="-1.5708 0 0" />
    <parent
      link="base_link" />
    <child
      link="wheel_left_link" />
    <axis
      xyz="0 0 1" />
  </joint>

  <link name="wheel_left_link">
    <inertial>
      <origin
        xyz="1.8976E-08 1.8319E-09 -0.033574"
        rpy="0 0 0" />
      <mass
        value="2.65022" />
      <inertia
        ixx="0.0015508"
        ixy="4.122E-10"
        ixz="-1.5313E-10"
        iyy="0.0015508"
        iyz="-2.3998E-11"
        izz="0.0029007" />
    </inertial>
    <visual>
      <origin
        xyz="0 0 0"
        rpy="0 0 0" />
      <geometry>
        <mesh
          filename="package://waiter_robot_1/meshes/wheel_L_link.STL" />
      </geometry>
      <material
        name="">
        <color
          rgba="0.79216 0.81961 0.93333 1" />
      </material>
    </visual>
    <collision>
      <origin
        xyz="0 0 0"
        rpy="0 0 0" />
      <geometry>
        <mesh
          filename="package://waiter_robot_1/meshes/wheel_L_link.STL" />
      </geometry>
    </collision>
  </link>

  <joint name="wheel_right_joint" type="continuous">
    <origin
      xyz="-0.075 -0.1942 -0.0125"
      rpy="1.5708 0 3.1416" />
    <parent
      link="base_link" />
    <child
      link="wheel_right_link" />
    <axis
      xyz="0 0 1" />
  </joint>

  <link name="wheel_right_link">
    <inertial>
      <origin
        xyz="1.8976E-08 -1.8319E-09 0.033574"
        rpy="0 0 0" />
      <mass
        value="2.65022" />
      <inertia
        ixx="0.0015508"
        ixy="-4.122E-10"
        ixz="1.5313E-10"
        iyy="0.0015508"
        iyz="-2.3998E-11"
        izz="0.0029007" />
    </inertial>
    <visual>
      <origin
        xyz="0 0 0"
        rpy="0 0 0" />
      <geometry>
        <mesh
          filename="package://waiter_robot_1/meshes/wheel_R_link.STL" />
      </geometry>
      <material
        name="">
        <color
          rgba="0.79216 0.81961 0.93333 1" />
      </material>
    </visual>
    <collision>
      <origin
        xyz="0 0 0"
        rpy="0 0 0" />
      <geometry>
        <mesh
          filename="package://waiter_robot_1/meshes/wheel_R_link.STL" />
      </geometry>
    </collision>
  </link>

  <joint name="castor_base_L_joint" type="continuous">
    <origin
      xyz="0.15472 0.0925 -0.0461"
      rpy="3.1416 0 0" />
    <parent
      link="base_link" />
    <child
      link="castor_base_L_link" />
    <axis
      xyz="0 0 1" />
  </joint>

  <link name="castor_base_L_link">
    <inertial>
      <origin
        xyz="-0.0098504 0.00015509 0.010437"
        rpy="0 0 0" />
      <mass
        value="0.5" />
      <inertia
        ixx="0.0001"
        ixy="0.0"
        ixz="0.0"
        iyy="0.0001"
        iyz="0.0"
        izz="0.0001" />
    </inertial>
    <visual>
      <origin
        xyz="0 0 0"
        rpy="0 0 0" />
      <geometry>
        <mesh
          filename="package://waiter_robot_1/meshes/castor_base_L_link.STL" />
      </geometry>
      <material
        name="">
        <color
          rgba="0.7 0.7 0.7 1" />
      </material>
    </visual>
    <collision>
      <origin
        xyz="0 0 0"
        rpy="0 0 0" />
      <geometry>
        <mesh
          filename="package://waiter_robot_1/meshes/castor_base_L_link.STL" />
      </geometry>
    </collision>
  </link>

  <joint name="castor_wheel_L_joint" type="continuous">
    <origin
      xyz="-0.019934 0 0.027"
      rpy="-1.5708 0 -3.1416" />
    <parent
      link="castor_base_L_link" />
    <child
      link="castor_wheel_L_link" />
    <axis
      xyz="0 0 1" />
  </joint>

  <link name="castor_wheel_L_link">
    <inertial>
      <origin
        xyz="1.1102E-16 6.9389E-17 -2.7409E-16"
        rpy="0 0 0" />
      <mass value="0.005" />
        <inertia 
          ixx="0.001"
          ixy="0.0" 
          ixz="0.0"
          iyy="0.001" 
          iyz="0.0"
          izz="0.001" />
    </inertial>
    <visual>
      <origin
        xyz="0 0 0"
        rpy="0 0 0" />
      <geometry>
        <mesh
          filename="package://waiter_robot_1/meshes/castor_wheel_L_link.STL" />
      </geometry>
      <material
        name="">
        <color
          rgba="0.1098 0.1098 0.1098 1" />
      </material>
    </visual>
    <collision>
      <origin
        xyz="0 0 0"
        rpy="0 0 0" />
      <geometry>
        <mesh
          filename="package://waiter_robot_1/meshes/castor_wheel_L_link.STL" />
      </geometry>
    </collision>
  </link>

  <joint name="castor_base_R_joint" type="continuous">
    <origin
      xyz="0.15472 -0.0915 -0.0461"
      rpy="3.1416 0 0" />
    <parent
      link="base_link" />
    <child
      link="castor_base_R_link" />
    <axis
      xyz="0 0 1" />
  </joint>

  <link name="castor_base_R_link">
    <inertial>
      <origin
        xyz="0.014375 0.00017948 0.041436"
        rpy="0 0 0" />
      <mass value="0.005" />
        <inertia 
          ixx="0.001"
          ixy="0.0" 
          ixz="0.0"
          iyy="0.001" 
          iyz="0.0"
          izz="0.001" />
    </inertial>
    <visual>
      <origin
        xyz="0 0 0"
        rpy="0 0 0" />
      <geometry>
        <mesh
          filename="package://waiter_robot_1/meshes/castor_base_R_link.STL" />
      </geometry>
      <material
        name="">
        <color
          rgba="0.7 0.7 0.7 1" />
      </material>
    </visual>
    <collision>
      <origin
        xyz="0 0 0"
        rpy="0 0 0" />
      <geometry>
        <mesh
          filename="package://waiter_robot_1/meshes/castor_base_R_link.STL" />
      </geometry>
    </collision>
  </link>


  <joint name="castor_wheel_R_joint" type="continuous">
    <origin
      xyz="-0.019934 0 0.027"
      rpy="-1.5708 0 -3.1416" />
    <parent
      link="castor_base_R_link" />
    <child
      link="castor_wheel_R_link" />
    <axis
      xyz="0 0 1" />
  </joint>

  <link name="castor_wheel_R_link">
    <inertial>
      <origin
        xyz="1.1102E-16 7.4593E-17 -3.0531E-16"
        rpy="0 0 0" />
      <mass
        value="0.2" />
      <inertia
        ixx="0.0001"
        ixy="0.0"
        ixz="0.0"
        iyy="0.0001"
        iyz="0.0"
        izz="0.0001" />
    </inertial>
    <visual>
      <origin
        xyz="0 0 0"
        rpy="0 0 0" />
      <geometry>
        <mesh
          filename="package://waiter_robot_1/meshes/castor_wheel_R_link.STL" />
      </geometry>
      <material
        name="">
        <color
          rgba="0.1098 0.1098 0.1098 1" />
      </material>
    </visual>
    <collision>
      <origin
        xyz="0 0 0"
        rpy="0 0 0" />
      <geometry>
        <mesh
          filename="package://waiter_robot_1/meshes/castor_wheel_R_link.STL" />
      </geometry>
    </collision>
  </link>


  <joint name="imu_joint" type="fixed">
    <parent link="base_link"/>
    <child link="imu_link"/>

   
      <!--  -0.075 0.1942 -0.0125
            -0.075 -0.1942 -0.0125 -->

    <origin xyz="-0.075 0 -0.0125" rpy="0 0 0"/>
  </joint>

  <link name="imu_link"/>

  <joint name="scan_joint" type="fixed">
    <parent link="base_link"/>
    <child link="base_scan"/>
    <origin xyz="-0.01 0.006 0.225" rpy="0 0 0"/>
  </joint>

  <link name="base_scan"/>

  <joint name="camera_joint" type="fixed">
    <parent link="base_link"/>
    <child link="camera_link"/>
    <origin xyz="0.16 0.005 0.165" rpy="0 0 0"/>
  </joint>

  <link name="camera_link"/>
    


</robot>